<?xml version="1.0" ?>
<robot name="converted_robot">
   <!--generated with mjcf_urdf_simple_converter (https://github.com/Yasu31/mjcf_urdf_simple_converter)-->
   <link name="panda0_link0">
      <inertial>
         <origin xyz="-0.029189765433072147 -0.0008794649788944781 0.0566031915141631" rpy="0.07341050648529257 -1.1999954549116758 3.0813768508296935"/>
         <mass value="2.91242"/>
         <inertia ixx="0.012252747599100987" iyy="0.011363973543842151" izz="0.008277853958097102" ixy="0" ixz="0" iyz="0"/>
      </inertial>
      <visual name="link0_viz">
         <origin xyz="-0.021984847396766805 -0.0008896593739903566 0.05397633820753746" rpy="0.0005388346167558566 -1.2165331197244809 -3.1263967787637412"/>
         <geometry>
            <mesh filename="../panda_meshes/converted_link0_viz.stl"/>
         </geometry>
         <material name="white"/>
      </visual>
      <visual name="link0_col">
         <origin xyz="-0.029189765433072147 -0.0008794649788944781 0.0566031915141631" rpy="0.07341050648529257 -1.1999954549116756 3.0813768508296935"/>
         <geometry>
            <mesh filename="../panda_meshes/converted_link0_col.stl"/>
         </geometry>
         <material name="white"/>
      </visual>
   </link>
   <link name="panda0_link1">
      <inertial>
         <origin xyz="1.139898131675401e-05 -0.03126552803743275 -0.06937330598619522" rpy="0.3507575596779383 -0.00032182734340535646 0.0006491282822314315"/>
         <mass value="2.7063"/>
         <inertia ixx="0.016028532125252317" iyy="0.015027567082764292" izz="0.0053318324257230895" ixy="0" ixz="0" iyz="0"/>
      </inertial>
      <visual name="link1_viz">
         <origin xyz="2.2333099850851852e-06 -0.03247938383820199 -0.06757587010715757" rpy="0.38337047278479996 0.00013917529691687136 -0.00037583015721226465"/>
         <geometry>
            <mesh filename="../panda_meshes/converted_link1_viz.stl"/>
         </geometry>
         <material name="white"/>
      </visual>
      <visual name="link1_col">
         <origin xyz="1.139898131675401e-05 -0.03126552803743275 -0.06937330598619522" rpy="0.3507575596779383 -0.00032182734340535646 0.0006491282822314315"/>
         <geometry>
            <mesh filename="../panda_meshes/converted_link1_col.stl"/>
         </geometry>
         <material name="white"/>
      </visual>
   </link>
   <link name="panda0_joint1_jointbody">
      <inertial>
         <origin xyz="0.0 0.0 0.0" rpy="0.0 0.0 0.0"/>
         <mass value="0.001"/>
         <inertia ixx="1e-09" iyy="1e-09" izz="1e-09" ixy="0" ixz="0" iyz="0"/>
      </inertial>
   </link>
   <joint type="revolute" name="panda0_joint1">
      <parent link="panda0_link0"/>
      <child link="panda0_joint1_jointbody"/>
      <origin xyz="0.0 0.0 0.333" rpy="0.0 0.0 0.0"/>
      <axis xyz="0.0 0.0 1.0"/>
      <limit lower="-2.8973" upper="2.8973" effort="87" velocity="2.1750"/>
   </joint>
   <joint type="fixed" name="panda0_joint1_offset">
      <parent link="panda0_joint1_jointbody"/>
      <child link="panda0_link1"/>
      <origin xyz="-0.0 -0.0 -0.0" rpy="0.0 0.0 0.0"/>
   </joint>
   <link name="panda0_link2">
      <inertial>
         <origin xyz="-1.3176553398219796e-05 -0.07032155252075616 0.031178239145109848" rpy="1.9167766250212852 3.863386533176083e-05 -0.00017520097652501398"/>
         <mass value="2.73046"/>
         <inertia ixx="0.016372443569979776" iyy="0.015352789885543734" izz="0.005393701000602283" ixy="0" ixz="0" iyz="0"/>
      </inertial>
      <visual name="link2_viz">
         <origin xyz="3.0683216894497734e-06 -0.06860273544627478 0.03220972526329134" rpy="1.9510753664554936 -0.0003840755309343358 -0.00012992900913055827"/>
         <geometry>
            <mesh filename="../panda_meshes/converted_link2_viz.stl"/>
         </geometry>
         <material name="white"/>
      </visual>
      <visual name="link2_col">
         <origin xyz="-1.3176553398219796e-05 -0.07032155252075616 0.031178239145109848" rpy="1.9167766250212854 3.8633865331982875e-05 -0.00017520097652501398"/>
         <geometry>
            <mesh filename="../panda_meshes/converted_link2_col.stl"/>
         </geometry>
         <material name="white"/>
      </visual>
   </link>
   <link name="panda0_joint2_jointbody">
      <inertial>
         <origin xyz="0.0 0.0 0.0" rpy="0.0 0.0 0.0"/>
         <mass value="0.001"/>
         <inertia ixx="1e-09" iyy="1e-09" izz="1e-09" ixy="0" ixz="0" iyz="0"/>
      </inertial>
   </link>
   <joint type="revolute" name="panda0_joint2">
      <parent link="panda0_link1"/>
      <child link="panda0_joint2_jointbody"/>
      <origin xyz="0.0 0.0 0.0" rpy="-1.5707963267948957 0.0 0.0"/>
      <axis xyz="0.0 0.0 1.0"/>
      <limit lower="-1.7628" upper="1.7628" effort="87" velocity="2.1750"/>
   </joint>
   <joint type="fixed" name="panda0_joint2_offset">
      <parent link="panda0_joint2_jointbody"/>
      <child link="panda0_link2"/>
      <origin xyz="-0.0 -0.0 -0.0" rpy="0.0 0.0 0.0"/>
   </joint>
   <link name="panda0_link3">
      <inertial>
         <origin xyz="0.04434830616977217 0.02492832585533832 -0.038129984535498415" rpy="0.6264281539686369 -0.6489124028865899 2.7888150643653677"/>
         <mass value="2.04104"/>
         <inertia ixx="0.008704799647862464" iyy="0.008526189975065757" izz="0.003659192966081935" ixy="0" ixz="0" iyz="0"/>
      </inertial>
      <visual name="link3_viz">
         <origin xyz="0.04853890609499807 0.03426551671468284 -0.031158988253545027" rpy="0.5620645638906847 -0.7724060532253757 3.0330843961200182"/>
         <geometry>
            <mesh filename="../panda_meshes/converted_link3_viz.stl"/>
         </geometry>
         <material name="white"/>
      </visual>
      <visual name="link3_dark_viz">
         <origin xyz="0.07826594887105137 0.08142974519737879 -0.00406312503726814" rpy="0.9103914044624806 0.05315688187292977 1.6361660028735399"/>
         <geometry>
            <mesh filename="../panda_meshes/converted_link3_dark_viz.stl"/>
         </geometry>
         <material name="white"/>
      </visual>
      <visual name="link3_col">
         <origin xyz="0.04434830616977217 0.02492832585533832 -0.038129984535498415" rpy="0.6264281539686367 -0.6489124028865898 2.788815064365368"/>
         <geometry>
            <mesh filename="../panda_meshes/converted_link3_col.stl"/>
         </geometry>
         <material name="white"/>
      </visual>
   </link>
   <link name="panda0_joint3_jointbody">
      <inertial>
         <origin xyz="0.0 0.0 0.0" rpy="0.0 0.0 0.0"/>
         <mass value="0.001"/>
         <inertia ixx="1e-09" iyy="1e-09" izz="1e-09" ixy="0" ixz="0" iyz="0"/>
      </inertial>
   </link>
   <joint type="revolute" name="panda0_joint3">
      <parent link="panda0_link2"/>
      <child link="panda0_joint3_jointbody"/>
      <origin xyz="0.0 -0.316 0.0" rpy="1.5707963267948963 0.0 0.0"/>
      <axis xyz="0.0 0.0 1.0"/>
      <limit lower="-2.8973" upper="2.8973" effort="87" velocity="2.1750"/>
   </joint>
   <joint type="fixed" name="panda0_joint3_offset">
      <parent link="panda0_joint3_jointbody"/>
      <child link="panda0_link3"/>
      <origin xyz="-0.0 -0.0 -0.0" rpy="0.0 0.0 0.0"/>
   </joint>
   <link name="panda0_link4">
      <inertial>
         <origin xyz="-0.038550294327056006 0.03952560974766748 0.024716241456280232" rpy="1.1575252530204931 0.36233734062035716 0.6286469250141417"/>
         <mass value="2.08129"/>
         <inertia ixx="0.009006880847790886" iyy="0.008831790803553114" izz="0.0037733476177690558" ixy="0" ixz="0" iyz="0"/>
      </inertial>
      <visual name="link4_viz">
         <origin xyz="-0.034582874588439914 0.03234212044021938 0.033850654593722634" rpy="1.0871199462729406 0.12778884236414356 0.7368487765625511"/>
         <geometry>
            <mesh filename="../panda_meshes/converted_link4_viz.stl"/>
         </geometry>
         <material name="white"/>
      </visual>
      <visual name="link4_dark_viz">
         <origin xyz="-0.005059102785114565 0.004050337360715577 0.08043076246399442" rpy="0.017273021275597378 -1.4866930441457151 2.4623856789347984"/>
         <geometry>
            <mesh filename="../panda_meshes/converted_link4_dark_viz.stl"/>
         </geometry>
         <material name="white"/>
      </visual>
      <visual name="link4_col">
         <origin xyz="-0.038550294327056006 0.03952560974766748 0.024716241456280232" rpy="1.1575252530204934 0.36233734062035716 0.6286469250141418"/>
         <geometry>
            <mesh filename="../panda_meshes/converted_link4_col.stl"/>
         </geometry>
         <material name="white"/>
      </visual>
   </link>
   <link name="panda0_joint4_jointbody">
      <inertial>
         <origin xyz="0.0 0.0 0.0" rpy="0.0 0.0 0.0"/>
         <mass value="0.001"/>
         <inertia ixx="1e-09" iyy="1e-09" izz="1e-09" ixy="0" ixz="0" iyz="0"/>
      </inertial>
   </link>
   <joint type="revolute" name="panda0_joint4">
      <parent link="panda0_link3"/>
      <child link="panda0_joint4_jointbody"/>
      <origin xyz="0.0825 0.0 0.0" rpy="1.5707963267948963 0.0 0.0"/>
      <axis xyz="0.0 0.0 1.0"/>
      <limit lower="-3.0718" upper="-0.4" effort="87" velocity="2.1750"/>
   </joint>
   <joint type="fixed" name="panda0_joint4_offset">
      <parent link="panda0_joint4_jointbody"/>
      <child link="panda0_link4"/>
      <origin xyz="-0.0 -0.0 -0.0" rpy="0.0 0.0 0.0"/>
   </joint>
   <link name="panda0_link5">
      <inertial>
         <origin xyz="-6.367762704756645e-05 0.03841237270479223 -0.10997017500559451" rpy="-0.27197776604413226 0.0020967099799318323 0.0011148540412214414"/>
         <mass value="3.00049"/>
         <inertia ixx="0.02618581046633134" iyy="0.02524217285800852" izz="0.005348180896198652" ixy="0" ixz="0" iyz="0"/>
      </inertial>
      <visual name="link5_viz">
         <origin xyz="-4.666435241145311e-05 0.052776968679302275 -0.09842004873748064" rpy="-0.2898827389028237 0.0013934871359873036 0.004714140157746488"/>
         <geometry>
            <mesh filename="../panda_meshes/converted_link5_viz.stl"/>
         </geometry>
         <material name="white"/>
      </visual>
      <visual name="link5_dark_viz">
         <origin xyz="-0.0001488770396455637 0.09673623430592755 -0.033143402548721564" rpy="0.0024935213048430382 0.0495754496836307 1.5665339126678446"/>
         <geometry>
            <mesh filename="../panda_meshes/converted_link5_dark_viz.stl"/>
         </geometry>
         <material name="white"/>
      </visual>
      <visual name="link5_col">
         <origin xyz="-6.367762704756645e-05 0.03841237270479223 -0.10997017500559451" rpy="-0.27197776604413215 0.0020967099799316102 0.0011148540412214136"/>
         <geometry>
            <mesh filename="../panda_meshes/converted_link5_col.stl"/>
         </geometry>
         <material name="white"/>
      </visual>
   </link>
   <link name="panda0_joint5_jointbody">
      <inertial>
         <origin xyz="0.0 0.0 0.0" rpy="0.0 0.0 0.0"/>
         <mass value="0.001"/>
         <inertia ixx="1e-09" iyy="1e-09" izz="1e-09" ixy="0" ixz="0" iyz="0"/>
      </inertial>
   </link>
   <joint type="revolute" name="panda0_joint5">
      <parent link="panda0_link4"/>
      <child link="panda0_joint5_jointbody"/>
      <origin xyz="-0.0825 0.384 0.0" rpy="-1.5707963267948957 0.0 0.0"/>
      <axis xyz="0.0 0.0 1.0"/>
      <limit lower="-2.8973" upper="2.8973" effort="12" velocity="2.6100"/>
   </joint>
   <joint type="fixed" name="panda0_joint5_offset">
      <parent link="panda0_joint5_jointbody"/>
      <child link="panda0_link5"/>
      <origin xyz="-0.0 -0.0 -0.0" rpy="0.0 0.0 0.0"/>
   </joint>
   <link name="panda0_link6">
      <inertial>
         <origin xyz="0.05100229436563991 0.00693267296652053 0.006168993350723507" rpy="-3.0615998737983494 -1.4277689715854653 0.04852070640740158"/>
         <mass value="1.3235"/>
         <inertia ixx="0.004018128712601542" iyy="0.0032851446119434107" izz="0.0020794507936098493" ixy="0" ixz="0" iyz="0"/>
      </inertial>
      <visual name="link6_viz">
         <origin xyz="0.05225810515193972 0.006880303416204388 0.008534384591949348" rpy="-3.069238024326488 -1.361132407610263 0.07945352484196389"/>
         <geometry>
            <mesh filename="../panda_meshes/converted_link6_viz.stl"/>
         </geometry>
         <material name="white"/>
      </visual>
      <visual name="link6_dark_viz">
         <origin xyz="0.04452175313348117 0.03310736130263862 0.022291914090851093" rpy="2.4222242876475013 -1.142765253857969 1.4465912259522415"/>
         <geometry>
            <mesh filename="../panda_meshes/converted_link6_dark_viz.stl"/>
         </geometry>
         <material name="white"/>
      </visual>
      <visual name="link6_col">
         <origin xyz="0.05100229436563991 0.00693267296652053 0.006168993350723507" rpy="-3.0615998737983494 -1.4277689715854653 0.04852070640740158"/>
         <geometry>
            <mesh filename="../panda_meshes/converted_link6_col.stl"/>
         </geometry>
         <material name="white"/>
      </visual>
   </link>
   <link name="panda0_joint6_jointbody">
      <inertial>
         <origin xyz="0.0 0.0 0.0" rpy="0.0 0.0 0.0"/>
         <mass value="0.001"/>
         <inertia ixx="1e-09" iyy="1e-09" izz="1e-09" ixy="0" ixz="0" iyz="0"/>
      </inertial>
   </link>
   <joint type="revolute" name="panda0_joint6">
      <parent link="panda0_link5"/>
      <child link="panda0_joint6_jointbody"/>
      <origin xyz="0.0 0.0 0.0" rpy="0.7853981633974483 -1.569670612918126 0.7853981633974483"/>
      <axis xyz="0.0 0.0 1.0"/>
      <limit lower="-1.6573" upper="2.1127" effort="12" velocity="2.6100"/>
   </joint>
   <joint type="fixed" name="panda0_joint6_offset">
      <parent link="panda0_joint6_jointbody"/>
      <child link="panda0_link6"/>
      <origin xyz="-0.0 -0.0 -0.0" rpy="0.0 0.0 0.0"/>
   </joint>
   <link name="panda0_link7">
      <inertial>
         <origin xyz="0.010361372115882629 0.010359603871236887 0.07910777287138845" rpy="3.138032285623005 -1.5171405401134985 -2.3520385516245224"/>
         <mass value="0.2"/>
         <inertia ixx="0.0003055845143865651" iyy="0.00025305457597797404" izz="0.00013397897780101473" ixy="0" ixz="0" iyz="0"/>
      </inertial>
      <visual name="link7_viz">
         <origin xyz="0.009733988117508616 0.009872670539790454 0.07875925516057704" rpy="-0.13338769587534194 -1.5230739991879987 -2.2265071063078636"/>
         <geometry>
            <mesh filename="../panda_meshes/converted_link7_viz.stl"/>
         </geometry>
         <material name="white"/>
      </visual>
      <visual name="link7_dark_viz">
         <origin xyz="0.042070756210377716 0.04213157284030423 0.08206855384772965" rpy="-1.5780280770386714 -1.3502633071313788 -2.3564758506473975"/>
         <geometry>
            <mesh filename="../panda_meshes/converted_link7_dark_viz.stl"/>
         </geometry>
         <material name="white"/>
      </visual>
      <visual name="link7_col">
         <origin xyz="0.010361372115882629 0.010359603871236887 0.07910777287138845" rpy="3.138032285623005 -1.5171405401134985 -2.3520385516245224"/>
         <geometry>
            <mesh filename="../panda_meshes/converted_link7_col.stl"/>
         </geometry>
         <material name="white"/>
      </visual>
   </link>
   <link name="panda0_joint7_jointbody">
      <inertial>
         <origin xyz="0.0 0.0 0.0" rpy="0.0 0.0 0.0"/>
         <mass value="0.001"/>
         <inertia ixx="1e-09" iyy="1e-09" izz="1e-09" ixy="0" ixz="0" iyz="0"/>
      </inertial>
   </link>
   <joint type="revolute" name="panda0_joint7">
      <parent link="panda0_link6"/>
      <child link="panda0_joint7_jointbody"/>
      <origin xyz="0.088 0.0 0.0" rpy="1.5696709361563443 -0.7853995448785632 0.0007952610088441947"/>
      <axis xyz="0.0 0.0 1.0"/>
      <limit lower="-2.8973" upper="2.8973" effort="12" velocity="2.6100"/>
   </joint>
   <joint type="fixed" name="panda0_joint7_offset">
      <parent link="panda0_joint7_jointbody"/>
      <child link="panda0_link7"/>
      <origin xyz="-0.0 -0.0 -0.0" rpy="0.0 0.0 0.0"/>
   </joint>
   <link name="ee_mount">
      <inertial>
         <origin xyz="0.0 0.0 0.11" rpy="0.0 0.0 -0.7853970066908718"/>
         <mass value="0.0"/>
         <inertia ixx="0.0" iyy="0.0" izz="0.0" ixy="0" ixz="0" iyz="0"/>
      </inertial>
   </link>
   <joint type="fixed" name="panda0_link72ee_mount_fixed">
      <parent link="panda0_link7"/>
      <child link="ee_mount"/>
      <origin xyz="0.0 0.0 0.11" rpy="0.0 0.0 -0.7853970066908718"/>
   </joint>
   <link name="robotiq_2f_85">
      <inertial>
         <origin xyz="2.2899356960443603e-07 -2.1897912859072486e-05 0.03187705344647061" rpy="-0.00220586909417746 -4.7474867137742294e-05 -0.024489885815227545"/>
         <mass value="0.2702422073195035"/>
         <inertia ixx="0.00024541309796528523" iyy="0.00022507216432187272" izz="0.00014451472455530157" ixy="0" ixz="0" iyz="0"/>
      </inertial>
      <visual name="robotiq-2f-base">
         <origin xyz="2.2899356960443603e-07 -2.1897912859072486e-05 0.03187705344647061" rpy="-0.00220586909417746 -4.7474867137742294e-05 -0.02448988581522754"/>
         <geometry>
            <mesh filename="../panda_meshes/converted_robotiq-2f-base.stl"/>
         </geometry>
         <material name="white"/>
      </visual>
      <visual name="robotiq-2f-base">
         <origin xyz="2.2899356960443603e-07 -2.1897912859072486e-05 0.03187705344647061" rpy="-0.00220586909417746 -4.7474867137742294e-05 -0.02448988581522754"/>
         <geometry>
            <mesh filename="../panda_meshes/converted_robotiq-2f-base.stl"/>
         </geometry>
         <material name="white"/>
      </visual>
   </link>
   <joint type="fixed" name="ee_mount2robotiq_2f_85_fixed">
      <parent link="ee_mount"/>
      <child link="robotiq_2f_85"/>
      <origin xyz="0.0 0.0 0.0" rpy="0.0 0.0 0.0"/>
   </joint>
   <link name="robotiq_2f_85_right_driver">
      <inertial>
         <origin xyz="0.0 0.01575 0.05295" rpy="1.4801282888669522 0.0 0.0"/>
         <mass value="0.2"/>
         <inertia ixx="0.00043212" iyy="0.000431866" izz="0.000360253" ixy="0" ixz="0" iyz="0"/>
      </inertial>
      <visual name="robotiq-2f-driver">
         <origin xyz="2.9693095360038857e-12 0.017754693326339378 0.001073141648831213" rpy="1.642515910368616 0.0 0.0"/>
         <geometry>
            <mesh filename="../panda_meshes/converted_robotiq-2f-driver.stl"/>
         </geometry>
         <material name="white"/>
      </visual>
      <visual name="robotiq-2f-coupler">
         <origin xyz="8.458042296975096e-13 0.03451208541474103 0.019117538318615818" rpy="0.0 0.12903875752327765 1.5707963267948966"/>
         <geometry>
            <mesh filename="../panda_meshes/converted_robotiq-2f-coupler.stl"/>
         </geometry>
         <material name="white"/>
      </visual>
      <visual name="robotiq-2f-coupler">
         <origin xyz="8.458042296975096e-13 0.03451208541474103 0.019117538318615818" rpy="0.0 0.12903875752327765 1.5707963267948966"/>
         <geometry>
            <mesh filename="../panda_meshes/converted_robotiq-2f-coupler.stl"/>
         </geometry>
         <material name="white"/>
      </visual>
   </link>
   <link name="robotiq_2f_85_right_driver_joint_jointbody">
      <inertial>
         <origin xyz="0.0 0.0 0.0" rpy="0.0 0.0 0.0"/>
         <mass value="0.001"/>
         <inertia ixx="1e-09" iyy="1e-09" izz="1e-09" ixy="0" ixz="0" iyz="0"/>
      </inertial>
   </link>
   <joint type="fixed" name="robotiq_2f_85_right_driver_joint">
      <parent link="robotiq_2f_85"/>
      <child link="robotiq_2f_85_right_driver_joint_jointbody"/>
      <origin xyz="0.0 0.0306011 0.054904" rpy="0.0 0.0 0.0"/>
      <axis xyz="1.0 0.0 0.0"/>
      <!-- <limit lower="0.0" upper="0.834" effort="100" velocity="100"/> -->
   </joint>
   <joint type="fixed" name="robotiq_2f_85_right_driver_joint_offset">
      <parent link="robotiq_2f_85_right_driver_joint_jointbody"/>
      <child link="robotiq_2f_85_right_driver"/>
      <origin xyz="-0.0 -0.0 -0.0" rpy="0.0 0.0 0.0"/>
   </joint>
   <link name="robotiq_2f_85_right_follower">
      <inertial>
         <origin xyz="0.0 0.0 0.055" rpy="1.5707963267948963 0.0 0.0"/>
         <mass value="0.2"/>
         <inertia ixx="0.000380833" iyy="0.000380833" izz="0.00036" ixy="0" ixz="0" iyz="0"/>
      </inertial>
      <visual name="robotiq-2f-follower">
         <origin xyz="-8.222505669797204e-08 -0.011045964820441189 0.012478641054290796" rpy="0.3343560463823991 1.1571605218474446e-05 4.019967359436549e-06"/>
         <geometry>
            <mesh filename="../panda_meshes/converted_robotiq-2f-follower.stl"/>
         </geometry>
         <material name="white"/>
      </visual>
      <visual name="robotiq-2f-pad">
         <origin xyz="-1.84784573132982e-10 -0.02140252522024533 0.031014528875892945" rpy="0.0 -4.425003626984392e-05 1.5707963267948966"/>
         <geometry>
            <mesh filename="../panda_meshes/converted_robotiq-2f-pad.stl"/>
         </geometry>
         <material name="white"/>
      </visual>
   </link>
   <link name="robotiq_2f_85_right_follower_joint_jointbody">
      <inertial>
         <origin xyz="0.0 0.0 0.0" rpy="0.0 0.0 0.0"/>
         <mass value="0.001"/>
         <inertia ixx="1e-09" iyy="1e-09" izz="1e-09" ixy="0" ixz="0" iyz="0"/>
      </inertial>
   </link>
   <joint type="fixed" name="robotiq_2f_85_right_follower_joint">
      <parent link="robotiq_2f_85_right_driver"/>
      <child link="robotiq_2f_85_right_follower_joint_jointbody"/>
      <origin xyz="0.0 0.0376 0.043" rpy="0.0 0.0 0.0"/>
      <axis xyz="1.0 0.0 0.0"/>
      <!-- <limit lower="-2.96706" upper="2.96706" effort="100" velocity="100"/> -->
   </joint>
   <joint type="fixed" name="robotiq_2f_85_right_follower_joint_offset">
      <parent link="robotiq_2f_85_right_follower_joint_jointbody"/>
      <child link="robotiq_2f_85_right_follower"/>
      <origin xyz="-0.0 -0.0 -0.0" rpy="0.0 0.0 0.0"/>
   </joint>
   <link name="robotiq_2f_85_right_spring_link">
      <inertial>
         <origin xyz="0.0 0.0 0.055" rpy="1.5707963267948963 0.0 0.0"/>
         <mass value="0.1"/>
         <inertia ixx="0.000190833" iyy="0.000190833" izz="0.00018" ixy="0" ixz="0" iyz="0"/>
      </inertial>
      <visual name="robotiq-2f-spring_link">
         <origin xyz="-8.650050113628342e-09 0.018162399838260603 0.021265809871824037" rpy="0.0 0.7068435008139309 1.5707963267948966"/>
         <geometry>
            <mesh filename="../panda_meshes/converted_robotiq-2f-spring_link.stl"/>
         </geometry>
         <material name="white"/>
      </visual>
   </link>
   <link name="robotiq_2f_85_right_spring_link_joint_jointbody">
      <inertial>
         <origin xyz="0.0 0.0 0.0" rpy="0.0 0.0 0.0"/>
         <mass value="0.001"/>
         <inertia ixx="1e-09" iyy="1e-09" izz="1e-09" ixy="0" ixz="0" iyz="0"/>
      </inertial>
   </link>
   <joint type="fixed" name="robotiq_2f_85_right_spring_link_joint">
      <parent link="robotiq_2f_85"/>
      <child link="robotiq_2f_85_right_spring_link_joint_jointbody"/>
      <origin xyz="0.0 0.012 0.0614" rpy="0.0 0.0 0.0"/>
      <axis xyz="1.0 0.0 0.0"/>
      <!-- <limit lower="-2.96706" upper="2.96706" effort="100" velocity="100"/> -->
   </joint>
   <joint type="fixed" name="robotiq_2f_85_right_spring_link_joint_offset">
      <parent link="robotiq_2f_85_right_spring_link_joint_jointbody"/>
      <child link="robotiq_2f_85_right_spring_link"/>
      <origin xyz="-0.0 -0.0 -0.0" rpy="0.0 0.0 0.0"/>
   </joint>
   <link name="robotiq_2f_85_left_driver">
      <inertial>
         <origin xyz="0.0 0.01575 0.05295" rpy="1.4801282888669522 0.0 0.0"/>
         <mass value="0.2"/>
         <inertia ixx="0.00043212" iyy="0.000431866" izz="0.000360253" ixy="0" ixz="0" iyz="0"/>
      </inertial>
      <visual name="robotiq-2f-driver">
         <origin xyz="2.9693095360038857e-12 0.017754693326339378 0.001073141648831213" rpy="1.642515910368616 0.0 0.0"/>
         <geometry>
            <mesh filename="../panda_meshes/converted_robotiq-2f-driver.stl"/>
         </geometry>
         <material name="white"/>
      </visual>
      <visual name="robotiq-2f-coupler">
         <origin xyz="8.458042296975096e-13 0.03451208541474103 0.019117538318615818" rpy="0.0 0.12903875752327765 1.5707963267948966"/>
         <geometry>
            <mesh filename="../panda_meshes/converted_robotiq-2f-coupler.stl"/>
         </geometry>
         <material name="white"/>
      </visual>
      <visual name="robotiq-2f-coupler">
         <origin xyz="8.458042296975096e-13 0.03451208541474103 0.019117538318615818" rpy="0.0 0.12903875752327765 1.5707963267948966"/>
         <geometry>
            <mesh filename="../panda_meshes/converted_robotiq-2f-coupler.stl"/>
         </geometry>
         <material name="white"/>
      </visual>
   </link>
   <link name="robotiq_2f_85_left_driver_joint_jointbody">
      <inertial>
         <origin xyz="0.0 0.0 0.0" rpy="0.0 0.0 0.0"/>
         <mass value="0.001"/>
         <inertia ixx="1e-09" iyy="1e-09" izz="1e-09" ixy="0" ixz="0" iyz="0"/>
      </inertial>
   </link>
   <joint type="fixed" name="robotiq_2f_85_left_driver_joint">
      <parent link="robotiq_2f_85"/>
      <child link="robotiq_2f_85_left_driver_joint_jointbody"/>
      <origin xyz="0.0 -0.0306011 0.054904" rpy="0.0 0.0 3.141592653589793"/>
      <axis xyz="1.0 0.0 0.0"/>
      <!-- <limit lower="0.0" upper="0.834" effort="100" velocity="100"/> -->
   </joint>
   <joint type="fixed" name="robotiq_2f_85_left_driver_joint_offset">
      <parent link="robotiq_2f_85_left_driver_joint_jointbody"/>
      <child link="robotiq_2f_85_left_driver"/>
      <origin xyz="-0.0 -0.0 -0.0" rpy="0.0 0.0 0.0"/>
   </joint>
   <link name="robotiq_2f_85_left_follower">
      <inertial>
         <origin xyz="0.0 0.0 0.055" rpy="1.5707963267948963 0.0 0.0"/>
         <mass value="0.2"/>
         <inertia ixx="0.000380833" iyy="0.000380833" izz="0.00036" ixy="0" ixz="0" iyz="0"/>
      </inertial>
      <visual name="robotiq-2f-follower">
         <origin xyz="-8.222505669797204e-08 -0.011045964820441189 0.012478641054290796" rpy="0.3343560463823991 1.1571605218474446e-05 4.019967359436549e-06"/>
         <geometry>
            <mesh filename="../panda_meshes/converted_robotiq-2f-follower.stl"/>
         </geometry>
         <material name="white"/>
      </visual>
      <visual name="robotiq-2f-pad">
         <origin xyz="-1.84784573132982e-10 -0.02140252522024533 0.031014528875892945" rpy="0.0 -4.425003626984392e-05 1.5707963267948966"/>
         <geometry>
            <mesh filename="../panda_meshes/converted_robotiq-2f-pad.stl"/>
         </geometry>
         <material name="white"/>
      </visual>
   </link>
   <link name="robotiq_2f_85_left_follower_joint_jointbody">
      <inertial>
         <origin xyz="0.0 0.0 0.0" rpy="0.0 0.0 0.0"/>
         <mass value="0.001"/>
         <inertia ixx="1e-09" iyy="1e-09" izz="1e-09" ixy="0" ixz="0" iyz="0"/>
      </inertial>
   </link>
   <joint type="fixed" name="robotiq_2f_85_left_follower_joint">
      <parent link="robotiq_2f_85_left_driver"/>
      <child link="robotiq_2f_85_left_follower_joint_jointbody"/>
      <origin xyz="0.0 0.0376 0.043" rpy="0.0 0.0 0.0"/>
      <axis xyz="1.0 0.0 0.0"/>
      <!-- <limit lower="-2.96706" upper="2.96706" effort="100" velocity="100"/> -->
   </joint>
   <joint type="fixed" name="robotiq_2f_85_left_follower_joint_offset">
      <parent link="robotiq_2f_85_left_follower_joint_jointbody"/>
      <child link="robotiq_2f_85_left_follower"/>
      <origin xyz="-0.0 -0.0 -0.0" rpy="0.0 0.0 0.0"/>
   </joint>
   <link name="robotiq_2f_85_left_spring_link">
      <inertial>
         <origin xyz="0.0 0.0 0.055" rpy="1.5707963267948963 0.0 0.0"/>
         <mass value="0.1"/>
         <inertia ixx="0.000190833" iyy="0.000190833" izz="0.00018" ixy="0" ixz="0" iyz="0"/>
      </inertial>
      <visual name="robotiq-2f-spring_link">
         <origin xyz="-8.650050113628342e-09 0.018162399838260603 0.021265809871824037" rpy="0.0 0.7068435008139309 1.5707963267948966"/>
         <geometry>
            <mesh filename="../panda_meshes/converted_robotiq-2f-spring_link.stl"/>
         </geometry>
         <material name="white"/>
      </visual>
   </link>
   <link name="robotiq_2f_85_left_spring_link_joint_jointbody">
      <inertial>
         <origin xyz="0.0 0.0 0.0" rpy="0.0 0.0 0.0"/>
         <mass value="0.001"/>
         <inertia ixx="1e-09" iyy="1e-09" izz="1e-09" ixy="0" ixz="0" iyz="0"/>
      </inertial>
   </link>
   <joint type="fixed" name="robotiq_2f_85_left_spring_link_joint">
      <parent link="robotiq_2f_85"/>
      <child link="robotiq_2f_85_left_spring_link_joint_jointbody"/>
      <origin xyz="0.0 -0.012 0.0614" rpy="0.0 0.0 3.141592653589793"/>
      <axis xyz="1.0 0.0 0.0"/>
      <!-- <limit lower="-2.96706" upper="2.96706" effort="100" velocity="100"/> -->
   </joint>
   <joint type="fixed" name="robotiq_2f_85_left_spring_link_joint_offset">
      <parent link="robotiq_2f_85_left_spring_link_joint_jointbody"/>
      <child link="robotiq_2f_85_left_spring_link"/>
      <origin xyz="-0.0 -0.0 -0.0" rpy="0.0 0.0 0.0"/>
   </joint>
   <material name="white">
      <color rgba="1 1 1 1"/>
   </material>
</robot>
